<robot name="go2w">
  <link name="base">
    <visual>
      <origin rpy="0 0 0" xyz="0 0 0" />
      <geometry>
        <box size="0.001 0.001 0.001" />
      </geometry>
    </visual>
  </link>
  <joint name="floating_base" type="floating">
    <origin rpy="0 0 0" xyz="0 0 0" />
    <parent link="base" />
    <child link="trunk" />
  </joint>
  <link name="trunk">
    <inertial>
      <origin xyz="0.021112 0 -0.005366" rpy="0 0 0" />
      <mass value="6.921" />
      <inertia ixx="0.02448" ixy="0.00012166" ixz="0.0014849" iyy="0.098077" iyz="-3.12E-05" izz="0.107" />
    </inertial>
    <visual>
      <origin rpy="0 0 0" xyz="0 0 0" />
      <geometry>
        <box size="0.3762 0.0935 0.114" />
      </geometry>
    </visual>
  </link>
  <link name="FL_hip">
    <inertial>
      <origin xyz="-0.0054 0.00194 -0.000105" rpy="0 0 0" />
      <mass value="0.678" />
      <inertia ixx="0.00048" ixy="-3.01E-06" ixz="1.11E-06" iyy="0.000884" iyz="-1.42E-06" izz="0.000596" />
    </inertial>
  </link>
  <joint name="LF_HAA" type="revolute">
    <origin xyz="0.1934 0.0465 0" rpy="0 0 0" />
    <parent link="trunk" />
    <child link="FL_hip" />
    <axis xyz="1 0 0" />
    <limit lower="-1.0472" upper="1.0472" effort="23.7" velocity="30.1" />
  </joint>
  <link name="FL_thigh">
    <inertial>
      <origin xyz="-0.00374 -0.0223 -0.0327" rpy="0 0 0" />
      <mass value="1.152" />
      <inertia ixx="0.00584" ixy="8.72E-05" ixz="-0.000289" iyy="0.0058" iyz="0.000808" izz="0.00103" />
    </inertial>
  </link>
  <joint name="LF_HFE" type="revolute">
    <origin xyz="0 0.0955 0" rpy="0 0 0" />
    <parent link="FL_hip" />
    <child link="FL_thigh" />
    <axis xyz="0 1 0" />
    <limit lower="-1.5707963267948966" upper="3.4907" effort="23.7" velocity="30.1" />
  </joint>
  <link name="FL_calf">
    <inertial>
      <origin xyz="0.00548 -0.000975 -0.115" rpy="0 0 0" />
      <mass value="0.154" />
      <inertia ixx="0.00108" ixy="3.4E-07" ixz="1.72E-05" iyy="0.0011" iyz="8.28E-06" izz="3.29E-05" />
    </inertial>
  </link>
  <joint name="LF_KFE" type="revolute">
    <origin xyz="0 0 -0.213" rpy="0 0 0" />
    <parent link="FL_thigh" />
    <child link="FL_calf" />
    <axis xyz="0 1 0" />
    <limit lower="-2.7227" upper="-0.83776" effort="35.55" velocity="20.07" />
  </joint>
  <link name="FL_foot_motor">
    <inertial>
      <origin xyz="0 0.0 0" rpy="0 0 0" />
      <mass value="0.646" />
      <inertia ixx="0.001" ixy="0" ixz="0" iyy="0.0016" iyz="0" izz="0.001" />
    </inertial>
  </link>
  <joint name="FL_foot_motor_joint" type="fixed">
    <origin xyz="-0.00 0.01 -0.2264" rpy="0 0.0 0" />
    <parent link="FL_calf" />
    <child link="FL_foot_motor" />
  </joint>
  <link name="FL_foot">
    <inertial>
      <origin xyz="0 0.06 0" rpy="0 0 0" />
      <mass value="0.520" />
      <inertia ixx="0.0007" ixy="0" ixz="0" iyy="0.0012" iyz="0" izz="0.0007" />
    </inertial>
  </link>
  <joint name="FL_foot_joint" type="fixed">
    <origin xyz="0 0 -0.2264" rpy="0 0 0" />
    <parent link="FL_calf" />
    <child link="FL_foot" />
  </joint>
  <link name="LF_FOOT" />
  <joint name="LF_foot_fixed" type="fixed" dont_collapse="true">
    <origin rpy="0 0 0" xyz="-0.07481 0 -0.27443" />
    <parent link="FL_calf" />
    <child link="LF_FOOT" />
  </joint>
  <link name="RL_hip">
    <inertial>
      <origin xyz="0.0054 0.00194 -0.000105" rpy="0 0 0" />
      <mass value="0.678" />
      <inertia ixx="0.00048" ixy="3.01E-06" ixz="-1.11E-06" iyy="0.000884" iyz="-1.42E-06" izz="0.000596" />
    </inertial>
  </link>
  <joint name="LH_HAA" type="revolute">
    <origin xyz="-0.1934 0.0465 0" rpy="0 0 0" />
    <parent link="trunk" />
    <child link="RL_hip" />
    <axis xyz="1 0 0" />
    <limit lower="-1.0472" upper="1.0472" effort="23.7" velocity="30.1" />
  </joint>
  <link name="RL_thigh">
    <inertial>
      <origin xyz="-0.00374 -0.0223 -0.0327" rpy="0 0 0" />
      <mass value="1.152" />
      <inertia ixx="0.00584" ixy="8.72E-05" ixz="-0.000289" iyy="0.0058" iyz="0.000808" izz="0.00103" />
    </inertial>
  </link>
  <joint name="LH_HFE" type="revolute">
    <origin xyz="0 0.0955 0" rpy="0 0 0" />
    <parent link="RL_hip" />
    <child link="RL_thigh" />
    <axis xyz="0 1 0" />
    <limit lower="-0.5236" upper="4.5379" effort="23.7" velocity="30.1" />
  </joint>
  <link name="RL_calf">
    <inertial>
      <origin xyz="0.00548 -0.000975 -0.115" rpy="0 0 0" />
      <mass value="0.154" />
      <inertia ixx="0.00108" ixy="3.4E-07" ixz="1.72E-05" iyy="0.0011" iyz="8.28E-06" izz="3.29E-05" />
    </inertial>
  </link>
  <joint name="LH_KFE" type="revolute">
    <origin xyz="0 0 -0.213" rpy="0 0 0" />
    <parent link="RL_thigh" />
    <child link="RL_calf" />
    <axis xyz="0 1 0" />
    <limit lower="-2.7227" upper="-0.83776" effort="35.55" velocity="20.07" />
  </joint>
  <link name="RL_foot_motor">
    <inertial>
      <origin xyz="0 0.0 0" rpy="0 0 0" />
      <mass value="0.646" />
      <inertia ixx="0.001" ixy="0" ixz="0" iyy="0.0016" iyz="0" izz="0.001" />
    </inertial>
  </link>
  <joint name="RL_foot_motor_joint" type="fixed">
    <origin xyz="0.00 0.01 -0.2264" rpy="0 0.0 0" />
    <parent link="RL_calf" />
    <child link="RL_foot_motor" />
  </joint>
  <link name="RL_foot">
    <inertial>
      <origin xyz="0 0.06 0" rpy="0 0 0" />
      <mass value="0.520" />
      <inertia ixx="0.0007" ixy="0" ixz="0" iyy="0.0012" iyz="0" izz="0.0007" />
    </inertial>
  </link>
  <joint name="RL_foot_joint" type="fixed">
    <origin xyz="0.0 0 -0.2264" rpy="0 0 0" />
    <parent link="RL_calf" />
    <child link="RL_foot" />
  </joint>
  <link name="LH_FOOT" />
  <joint name="LH_foot_fixed" type="fixed" dont_collapse="true">
    <origin rpy="0 0 0" xyz="-0.07481 0 -0.27443" />
    <parent link="RL_calf" />
    <child link="LH_FOOT" />
  </joint>
  <link name="FR_hip">
    <inertial>
      <origin xyz="-0.0054 -0.00194 -0.000105" rpy="0 0 0" />
      <mass value="0.678" />
      <inertia ixx="0.00048" ixy="3.01E-06" ixz="1.11E-06" iyy="0.000884" iyz="1.42E-06" izz="0.000596" />
    </inertial>
  </link>
  <joint name="RF_HAA" type="revolute">
    <origin xyz="0.1934 -0.0465 0" rpy="0 0 0" />
    <parent link="trunk" />
    <child link="FR_hip" />
    <axis xyz="1 0 0" />
    <limit lower="-1.0472" upper="1.0472" effort="23.7" velocity="30.1" />
  </joint>
  <link name="FR_thigh">
    <inertial>
      <origin xyz="-0.00374 0.0223 -0.0327" rpy="0 0 0" />
      <mass value="1.152" />
      <inertia ixx="0.00584" ixy="-8.72E-05" ixz="-0.000289" iyy="0.0058" iyz="-0.000808" izz="0.00103" />
    </inertial>
  </link>
  <joint name="RF_HFE" type="revolute">
    <origin xyz="0 -0.0955 0" rpy="0 0 0" />
    <parent link="FR_hip" />
    <child link="FR_thigh" />
    <axis xyz="0 1 0" />
    <limit lower="-1.5707963267948966" upper="3.4907" effort="23.7" velocity="30.1" />
  </joint>
  <link name="FR_calf">
    <inertial>
      <origin xyz="0.00548 0.000975 -0.115" rpy="0 0 0" />
      <mass value="0.154" />
      <inertia ixx="0.00108" ixy="-3.4E-07" ixz="1.72E-05" iyy="0.0011" iyz="-8.28E-06" izz="3.29E-05" />
    </inertial>
  </link>
  <joint name="RF_KFE" type="revolute">
    <origin xyz="0 0 -0.213" rpy="0 0 0" />
    <parent link="FR_thigh" />
    <child link="FR_calf" />
    <axis xyz="0 1 0" />
    <limit lower="-2.7227" upper="-0.83776" effort="35.55" velocity="20.07" />
  </joint>
  <link name="FR_foot_motor">
    <inertial>
      <origin xyz="0 0.0 0" rpy="0 0 0" />
      <mass value="0.646" />
      <inertia ixx="0.001" ixy="0" ixz="0" iyy="0.0016" iyz="0" izz="0.001" />
    </inertial>
  </link>
  <joint name="FR_foot_motor_joint" type="fixed">
    <origin xyz="0.0 -0.01 -0.2264" rpy="0 0.0 0" />
    <parent link="FR_calf" />
    <child link="FR_foot_motor" />
  </joint>
  <link name="FR_foot">
    <inertial>
      <origin xyz="0 -0.06 0" rpy="0 0 0" />
      <mass value="0.520" />
      <inertia ixx="0.0007" ixy="0" ixz="0" iyy="0.0012" iyz="0" izz="0.0007" />
    </inertial>
  </link>
  <joint name="FR_foot_joint" type="fixed">
    <origin xyz="0 0 -0.2264" rpy="0 0 0" />
    <parent link="FR_calf" />
    <child link="FR_foot" />
  </joint>
  <link name="RF_FOOT" />
  <joint name="RF_foot_fixed" type="fixed" dont_collapse="true">
    <origin rpy="0 0 0" xyz="-0.07481 0 -0.27443" />
    <parent link="FR_calf" />
    <child link="RF_FOOT" />
  </joint>
  <link name="RR_hip">
    <inertial>
      <origin xyz="0.0054 -0.00194 -0.000105" rpy="0 0 0" />
      <mass value="0.678" />
      <inertia ixx="0.00048" ixy="-3.01E-06" ixz="-1.11E-06" iyy="0.000884" iyz="1.42E-06" izz="0.000596" />
    </inertial>
  </link>
  <joint name="RH_HAA" type="revolute">
    <origin xyz="-0.1934 -0.0465 0" rpy="0 0 0" />
    <parent link="trunk" />
    <child link="RR_hip" />
    <axis xyz="1 0 0" />
    <limit lower="-1.0472" upper="1.0472" effort="23.7" velocity="30.1" />
  </joint>
  <link name="RR_thigh">
    <inertial>
      <origin xyz="-0.00374 0.0223 -0.0327" rpy="0 0 0" />
      <mass value="1.152" />
      <inertia ixx="0.00584" ixy="-8.72E-05" ixz="-0.000289" iyy="0.0058" iyz="-0.000808" izz="0.00103" />
    </inertial>
  </link>
  <joint name="RH_HFE" type="revolute">
    <origin xyz="0 -0.0955 0" rpy="0 0 0" />
    <parent link="RR_hip" />
    <child link="RR_thigh" />
    <axis xyz="0 1 0" />
    <limit lower="-0.5236" upper="4.5379" effort="23.7" velocity="30.1" />
  </joint>
  <link name="RR_calf">
    <inertial>
      <origin xyz="0.00548 0.000975 -0.115" rpy="0 0 0" />
      <mass value="0.154" />
      <inertia ixx="0.00108" ixy="-3.4E-07" ixz="1.72E-05" iyy="0.0011" iyz="-8.28E-06" izz="3.29E-05" />
    </inertial>
  </link>
  <joint name="RH_KFE" type="revolute">
    <origin xyz="0 0 -0.213" rpy="0 0 0" />
    <parent link="RR_thigh" />
    <child link="RR_calf" />
    <axis xyz="0 1 0" />
    <limit lower="-2.7227" upper="-0.83776" effort="35.55" velocity="20.07" />
  </joint>
  <link name="RR_foot_motor">
    <inertial>
      <origin xyz="0 0.0 0" rpy="0 0 0" />
      <mass value="0.646" />
      <inertia ixx="0.001" ixy="0" ixz="0" iyy="0.0016" iyz="0" izz="0.001" />
    </inertial>
  </link>
  <joint name="RR_foot_motor_joint" type="fixed">
    <origin xyz="0.00 -0.01 -0.2264" rpy="0 0.0 0" />
    <parent link="RR_calf" />
    <child link="RR_foot_motor" />
  </joint>
  <link name="RR_foot">
    <inertial>
      <origin xyz="0 -0.06 0" rpy="0 0 0" />
      <mass value="0.520" />
      <inertia ixx="0.0007" ixy="0" ixz="0" iyy="0.0012" iyz="0" izz="0.0007" />
    </inertial>
  </link>
  <joint name="RR_foot_joint" type="fixed">
    <origin xyz="-0.0 0 -0.2264" rpy="0 0 0" />
    <parent link="RR_calf" />
    <child link="RR_foot" />
  </joint>
  <link name="RH_FOOT" />
  <joint name="RH_foot_fixed" type="fixed" dont_collapse="true">
    <origin rpy="0 0 0" xyz="-0.07481 0 -0.27443" />
    <parent link="RR_calf" />
    <child link="RH_FOOT" />
  </joint>
</robot>